Workbook

Sheet Instrucciones
B1: OjoAlBondi — Plan de pruebas (Etapa 1, RF-25 y beta)
B2: 59 criterios de aceptación: los 56 de la Especificación vigente v10, ordenados para ejecutarse en secuencia, más los agregados desde el 11/10/2026 al final de la lista.
B4: Antes de empezar
B5: 1. Base de datos actualizada (migraciones 004 a 006, o instalación completa) y paradas cargadas. CA-RNF01-3 necesita la migración 006.
B6: 2. Datos de prueba cargados: npm run datos-prueba:borrar y luego npm run datos-prueba (desde ojoalbondi-backend).
B7: 3. "Confirm email" desactivado en Supabase. App abierta en Expo Go (SDK 57) con el .env del proyecto.
B9: Cuentas de prueba (contraseña Prueba123!)
B10: • vecino1@prueba.ojoalbondi … vecino8@prueba.ojoalbondi → ciudadanos con reclamos cargados.
B11: • tratado@prueba.ojoalbondi → Tratado del Pilar: suscripción activa a la 501 (opera también la 503, sin suscripción).
B12: • pilarbus@prueba.ojoalbondi → Pilar Bus: suscripción activa a la 510.
B13: • municipio@prueba.ojoalbondi → ve todas las líneas.
B15: Cómo registrar los resultados
... B38: • CA-RF03-9 (12/10/2026): aviso de permiso de ubicación en el buscador del mapa de paradas (cambio de SelectorParada.tsx posterior al N° 40).

Sheet Plan de pruebas
A1: N° | B1: ID | C1: Requerimiento | D1: Bloque | E1: Cuenta | F1: Tipo | G1: Dado | H1: Cuando | I1: Entonces (resultado esperado) | J1: Cómo probarlo | K1: Resultado | L1: Observaciones | M1: Probado por | N1: Fecha
A2: 1 | B2: CA-RF01-1 | C2: RF-01 Registro | D2: 1. Registro e inicio de sesión | E2: Correo nuevo (sin cuenta) | F2: App | G2: Estoy en Registro con todos los campos completos y válidos | H2: Toco "Registrarme" | I2: Se crea una cuenta de ciudadano, se muestra "Cuenta creada" y paso a Login | K2: Pasa | L2: Correo usado: realemii72+ojoalbondi1@gmail.com. Se mostró "Cuenta creada" y pasó a Login. Como la beta tiene "Confirm email" activo, la cuenta queda sin confirmar y no puede entrar hasta abrir el mail. Ojo: el SMTP incluido de Supabase permite 2 mails por hora; al pasarse, el alta falla con 429 (over_email_send_rate_limit), la cuenta no se crea y la app muestra solo "Ocurrió un error. Intentá de nuevo." (pasó con ojoalbondi.app@gmail.com). | M2: Claude en VS Code, emulador | N2: 46306
A3: 2 | B3: CA-RF01-2 | C3: RF-01 Registro | D3: 1. Registro e inicio de sesión | E3: Correo nuevo (sin cuenta) | F3: App | G3: Dejé uno o más campos vacíos | H3: Toco "Registrarme" | I3: Se muestra "Completá todos los campos." y no se crea la cuenta | K3: Pasa | L3: Solo con Nombre completo: se mostró "Completá todos los campos." y la app quedó en Registro. | M3: Claude en VS Code, emulador | N3: 46306
A4: 3 | B4: CA-RF01-3 | C4: RF-01 Registro | D4: 1. Registro e inicio de sesión | E4: Correo nuevo (sin cuenta) | F4: App | G4: La contraseña tiene menos de 6 caracteres, o las dos contraseñas no coinciden | H4: Toco "Registrarme" | I4: Se muestra el mensaje correspondiente y no se crea la cuenta | K4: Pasa | L4: Contraseña de 3 caracteres: "La contraseña debe tener al menos 6 caracteres.". Contraseñas distintas: "Las contraseñas no coinciden.". En los dos casos quedó en Registro (captura con las dos pantallas). | M4: Claude en VS Code, emulador | N4: 46306
A5: 4 | B5: CA-RF01-4 | C5: RF-01 Registro | D5: 1. Registro e inicio de sesión | E5: Correo nuevo (sin cuenta) | F5: App | G5: Ya existe una cuenta con ese correo | H5: Toco "Registrarme" | I5: Se muestra "Ya existe una cuenta con ese correo." y no se crea otra | K5: Pasa | L5: Con vecino1@prueba.ojoalbondi (cuenta confirmada): se mostró "Ya existe una cuenta con ese correo." y quedó en Registro. Nota: si la cuenta existente todavía NO confirmó el correo (probado con realemii72+ojoalbondi1@gmail.com), la app muestra "Cuenta creada": Supabase devuelve el mismo usuario (mismo id en los logs de Auth, no crea otro) y reenvía el mail de confirmación. | M5: Claude en VS Code, emulador | N5: 46306
A6: 5 | B6: CA-RF01-5 | C6: RF-01 Registro | D6: 1. Registro e inicio de sesión | E6: Correo nuevo (sin cuenta) | F6: App | G6: Estoy eligiendo la fecha de nacimiento | H6: Abro el calendario | I6: No puedo elegir una fecha posterior a hoy | K6: Pasa | L6: En el calendario de Android los días posteriores a hoy (11/10/2026) aparecen grises y al tocarlos no se seleccionan; no hay flecha al mes siguiente y la lista de años termina en 2026. | M6: Claude en VS Code, emulador | N6: 46306
A7: 6 | B7: CA-RF02-1 | C7: RF-02 Inicio de sesión | D7: 1. Registro e inicio de sesión | E7: vecino1@prueba.ojoalbondi | F7: App | G7: Tengo una cuenta de ciudadano | H7: Ingreso correo y contraseña correctos | I7: Entro a la pantalla Reportar | K7: Pasa | L7: vecino1@prueba.ojoalbondi / Prueba123!: entró a Reportar ("Hola, Lucía" y Últimos reportes). En el emulador la barra inferior salió sin íconos porque Expo Go no pudo bajar la fuente Ionicons del servidor de desarrollo (problema del entorno, no de la app). | M7: Claude en VS Code, emulador | N7: 46306
A8: 7 | B8: CA-RF02-2 | C8: RF-02 Inicio de sesión | D8: 1. Registro e inicio de sesión | E8: vecino1@prueba.ojoalbondi | F8: App | G8: Ingresé un correo o una contraseña incorrectos | H8: Toco "Iniciar sesión" | I8: Se muestra "El correo o la contraseña son incorrectos." y no entro | K8: Pasa | L8: vecino1@prueba.ojoalbondi con contraseña incorrecta: se mostró "El correo o la contraseña son incorrectos." y quedó en Login. | M8: Claude en VS Code, emulador | N8: 46306
A9: 8 | B9: CA-RF02-3 | C9: RF-02 Inicio de sesión | D9: 1. Registro e inicio de sesión | E9: vecino1@prueba.ojoalbondi | F9: App | G9: Escribí mi correo en Login | H9: Toco "¿Olvidaste tu contraseña?" | I9: Recibo un mail para restablecerla y la app me avisa que lo envió. Si el correo está vacío, la app me pide escribirlo | K9: Pasa | L9: Probado 12/10/2026 en la beta con ojoalbondi.app@gmail.com (en lugar de vecino1, para poder ver el mail). Con el correo vacío, la app mostró "Escribí tu correo arriba y tocá de nuevo “¿Olvidaste tu contraseña?”." Con el correo escrito mostró "Revisá tu correo — Te enviamos un mail a ojoalbondi.app@gmail.com para restablecer tu contraseña." y el mail llegó (confirmado por el equipo). No apareció el aviso de demasiados correos. Captura: correo vacío a la izquierda y envío a la derecha. No se abrió el enlace; probablemente redirija a localhost:3000 como el de confirmación (ver CA-RF02-6). | M9: Claude (automatizado) | N9: 46307
A10: 9 | B10: CA-RF02-4 | C10: RF-02 Inicio de sesión | D10: 1. Registro e inicio de sesión | E10: vecino1@prueba.ojoalbondi | F10: App | G10: Inicié sesión | H10: Cierro la app y la vuelvo a abrir | I10: Sigo con la sesión iniciada. Al tocar "Cerrar sesión" vuelvo a Bienvenida | K10: Pasa | L10: Con vecino1: cerré Expo Go del todo (force-stop) y al reabrir el proyecto siguió en Reportar con la sesión iniciada (probado dos veces). "Cerrar sesión" en Ajustes volvió a Bienvenida. Detalle visual: en Ajustes, al desplazar, el título "Ajustes" queda superpuesto con la barra de estado del celular. | M10: Claude en VS Code, emulador | N10: 46306
A11: 10 | B11: CA-RN02-1 | C11: RN-02 Cuentas institucionales | D11: 1. Registro e inicio de sesión | E11: La cuenta creada en CA-RF01-1 | F11: Base de datos | G11: Me registro desde la app | H11: Se crea mi cuenta | I11: La cuenta es siempre de ciudadano | J11: select rol from perfiles where id = '<id de la cuenta nueva>'; → 'ciudadano' | K11: Pasa | L11: Verificado en la base simulando el alta (insert en auth.users con metadatos que piden rol admin): el perfil queda "ciudadano". Se deshizo. El alta desde la app se mira en CA-RF01-1. | M11: Claude (SQL en la beta, en nombre de la cuenta del caso) | N11: 46306
A12: 11 | B12: CA-RF03-1 | C12: RF-03 Crear reclamo | D12: 2. Ciudadano: crear reclamo | E12: vecino1@prueba.ojoalbondi | F12: App | G12: Completé línea, interno o patente, sentido, motivo, fecha, hora y ubicación | H12: Toco "Enviar reporte" | I12: El reclamo se registra y paso a Confirmación | K12: Pasa | L12: Probado 12/10/2026 en la beta con vecino1 (letra 1.0, tema Claro): línea 501, hacia Pilar, Demora/poca frecuencia, interno 1245, descripción "PRUEBA EMULADOR CA-RF03-1", fecha de hoy, 10:30 hs, Parada Bolívar e Ituzaingó (elegida en el mapa). Al tocar "Enviar reporte" pasó a Confirmación con OB-2026-0151; en la base quedó con todos esos datos y la parada vinculada. Captura: formulario (2 partes) y Confirmación. | M12: Claude (automatizado) | N12: 46307
A13: 12 | B13: CA-RF03-2 | C13: RF-03 Crear reclamo | D13: 2. Ciudadano: crear reclamo | E13: vecino1@prueba.ojoalbondi | F13: App | G13: Falta alguno de los campos obligatorios | H13: Toco "Enviar reporte" | I13: Se muestra qué falta completar y el reclamo no se envía | K13: Pasa | L13: Probado 12/10/2026: con el formulario vacío, "Enviar reporte" muestra "Completá línea, sentido, motivo, fecha, horario y ubicación." y queda en Crear reporte. Nota: el mensaje es siempre el mismo, lista todos los obligatorios aunque falte uno solo (no marca cuál falta). | M13: Claude (automatizado) | N13: 46307
A14: 13 | B14: CA-RF03-3 | C14: RF-03 Crear reclamo | D14: 2. Ciudadano: crear reclamo | E14: vecino1@prueba.ojoalbondi | F14: App | G14: Elegí el motivo "Robo, hurto o agresión" | H14: Miro el formulario | I14: Veo el aviso del 911, y puedo enviar el reclamo sin completar interno o patente | K14: Pasa | L14: Probado 12/10/2026: con "Robo, hurto o agresión en la parada del colectivo" aparece "🚨 Si estás en peligro o acabás de sufrir un delito, llamá al 911. Este reclamo no reemplaza una denuncia policial." y la etiqueta pasa a "Interno o patente (opcional)". Con el interno vacío se envió (OB-2026-0152, descripción "PRUEBA EMULADOR CA-RF03-3"). | M14: Claude (automatizado) | N14: 46307
A15: 14 | B15: CA-RF03-4 | C15: RF-03 Crear reclamo | D15: 2. Ciudadano: crear reclamo | E15: vecino1@prueba.ojoalbondi | F15: App | G15: Elegí cualquier otro motivo y dejé vacío interno o patente | H15: Toco "Enviar reporte" | I15: El reclamo no se envía y se indica que el campo es obligatorio | K15: Pasa | L15: Probado 12/10/2026: con todo completo (501, hacia Pilar, Demora/poca frecuencia, hoy 10:30, "Rivadavia 500, Pilar") y el interno vacío, se muestra "El interno o la patente es obligatorio para este motivo." y no se envía. | M15: Claude (automatizado) | N15: 46307
A16: 15 | B16: CA-RF03-5 | C16: RF-03 Crear reclamo | D16: 2. Ciudadano: crear reclamo | E16: vecino1@prueba.ojoalbondi | F16: App | G16: Elegí el motivo "Hice señas y el colectivo no frenó" | H16: Miro el campo interno o patente | I16: Veo la ayuda general y la ayuda adicional sobre mirar el número en la parte de atrás | K16: Pasa | L16: Probado 12/10/2026: con "Hice señas y el colectivo no frenó" se ven la ayuda general ("El número de interno está pintado en el frente, los costados y la parte de atrás del colectivo.") y la adicional en negrita ("Si no frenó, fijate el número en la parte de atrás cuando se aleja."). | M16: Claude (automatizado) | N16: 46307
A17: 16 | B17: CA-RF03-6 | C17: RF-03 Crear reclamo | D17: 2. Ciudadano: crear reclamo | E17: vecino1@prueba.ojoalbondi | F17: App | G17: Elegí una línea | H17: Abro el campo Sentido | I17: Solo veo los destinos de esa línea | K17: Pasa | L17: Probado 12/10/2026 con la línea 501: Sentido ofrece solo "hacia Pilar", "hacia San Alejo", "hacia Villa Astolfi" y "hacia Villa Rosa", que son los extremos de sus 3 ramales activos en la base (Pilar–Villa Rosa, Pilar–San Alejo, Villa Rosa–Villa Astolfi). | M17: Claude (automatizado) | N17: 46307
A18: 17 | B18: CA-RF03-7 | C18: RF-03 Crear reclamo | D18: 2. Ciudadano: crear reclamo | E18: vecino1@prueba.ojoalbondi | F18: App | G18: La fecha del hecho es hoy | H18: Elijo una hora posterior a la actual y envío | I18: El reclamo no se envía y se indica que el horario no puede ser posterior a la hora actual | K18: Pasa | L18: Probado 12/10/2026: fecha de hoy y 23:30 hs (el emulador marcaba 15:10) → "El horario del hecho no puede ser posterior a la hora actual." y no se envía. Ojo: el emulador está en zona horaria GMT (3 h adelante de Argentina) y la app compara con la hora del celular. | M18: Claude (automatizado) | N18: 46307
A19: 18 | B19: CA-RF03-8 | C19: RF-03 Crear reclamo | D19: 2. Ciudadano: crear reclamo | E19: vecino1@prueba.ojoalbondi | F19: App | G19: Abrí el mapa de paradas | H19: Busco una calle y altura, toco una parada y confirmo | I19: El mapa se centra en la dirección y el campo Ubicación queda con "Parada <nombre>" y un mapa chico de la parada | K19: Pasa | L19: Revisión del Cambio N° 40 (12/10/2026, vecino1, sin enviar reclamos). 1) Buscador del mapa de paradas: busqué "Lorenzo Lopez 600"; el mapa se centró en Lorenzo López y Rivadavia y el texto siguió diciendo "Lorenzo Lopez 600" (antes lo cambiaba por "Bernardino Rivadavia 702, Pilar"). Captura CA40-1. 2) Parada sin líneas cargadas (Bolívar e Ituzaingó, lineas vacío en la base): la ficha dice "Todavía no sabemos qué líneas paran acá" en el mapa de paradas de Crear reporte y en la pestaña Mapa (antes "Líneas sin informar"). Captura CA40-2 (selector y pestaña Mapa). 3) Foto > Galería en este emulador (sin selector de fotos del sistema): aparece "No se pudo abrir la galería. Probá sacando la foto con la cámara." (antes no pasaba nada). Captura CA40-3. Observación nueva: el buscador usa el geocodificador del celular, que en Android necesita el permiso de ubicación; sin ese permiso responde "No encontramos esa dirección." aunque la dirección exista (pasó al borrar los datos de Expo Go, hasta volver a dar el permiso con "Probar" en Ajustes). Conviene avisar que hace falta la ubicación o usar otro geocodificador. | Probado 12/10/2026: en "Elegir la parada en el mapa" busqué "Lorenzo Lopez 600": el mapa se centró con el pin en Lorenzo López y Rivadavia. Toqué la parada Bolívar e Ituzaingó (visible con "Paradas de la línea 501") y confirmé: Ubicación quedó "Parada Bolívar e Ituzaingó" con el mapa chico de la parada. Detalles: el buscador reemplazó mi texto por "Bernardino Rivadavia 702, Pilar" (la misma esquina, nombrada por la otra calle), y la ficha de esa parada dice "Líneas sin informar" aunque aparece con el filtro de la 501. Captura: búsqueda, parada elegida y formulario. | M19: Claude (automatizado) | N19: 46307
A20: 19 | B20: CA-RF04-1 | C20: RF-04 Confirmación | D20: 2. Ciudadano: crear reclamo | E20: vecino1@prueba.ojoalbondi | F20: App | G20: Envié un reclamo con conexión | H20: Llego a Confirmación | I20: Veo un ticket OB-AAAA-NNNN que no se repite, el resumen del reclamo y el estado Recibido | K20: Pasa | L20: Probado 12/10/2026: Confirmación muestra "Reporte enviado", "Ticket N° OB-2026-0151", Línea 501, Motivo, Horario 10:30 hs, Ubicación y Estado "Recibido". En la base el ticket aparece una sola vez (formato OB-AAAA-NNNN). | M20: Claude (automatizado) | N20: 46307
A21: 20 | B21: CA-RF04-2 | C21: RF-04 Confirmación | D21: 2. Ciudadano: crear reclamo | E21: vecino1@prueba.ojoalbondi | F21: App | G21: Estoy en Confirmación | H21: Toco "Ver mis reportes" | I21: Veo el reclamo nuevo primero en la lista | K21: Pasa | L21: Probado 12/10/2026: desde Confirmación, "Ver mis reportes" abre Mis reportes con OB-2026-0151 (12/10/2026, Recibido) primero en la lista. | M21: Claude (automatizado) | N21: 46307
A22: 21 | B22: CA-RF05-1 | C22: RF-05 Inicio y Mis reportes | D22: 3. Ciudadano: inicio, mis reportes y ajustes | E22: vecino1@prueba.ojoalbondi | F22: App | G22: Tengo reclamos registrados | H22: Entro a Reportar | I22: Veo el saludo con mi nombre y mis 3 últimos reclamos | K22: Pasa | L22: Probado 12/10/2026 con vecino1: Reportar muestra "Hola, Lucía" y los 3 últimos: OB-2026-0152, OB-2026-0151 y OB-2026-0053. | M22: Claude (automatizado) | N22: 46307
A23: 22 | B23: CA-RF05-2 | C23: RF-05 Inicio y Mis reportes | D23: 3. Ciudadano: inicio, mis reportes y ajustes | E23: vecino1@prueba.ojoalbondi | F23: App | G23: Tengo reclamos registrados | H23: Entro a Mis reportes | I23: Veo todos mis reclamos, los más recientes primero, con su estado, y ninguno de otros usuarios | K23: Pasa | L23: Probado 12/10/2026 con vecino1: Mis reportes lista 23 reclamos, los mismos 23 que tiene en la base (ninguno de otros usuarios), con su estado (Recibido, En revisión, Atendido), ordenados por fecha de registro del más nuevo al más viejo. Captura: comienzo y final de la lista. | M23: Claude (automatizado) | N23: 46307
... A27: 26 | B27: CA-RF06-3 | C27: RF-06 Ajustes | D27: 3. Ciudadano: inicio, mis reportes y ajustes | E27: vecino1@prueba.ojoalbondi | F27: App | G27: Estoy en Ajustes | H27: Toco "Probar" en Ubicación | I27: La app pide el permiso de ubicación y muestra si fue otorgado o denegado | K27: Pasa | L27: Probar abrió el diálogo de permiso de Android. Con "Don't allow" mostró "❌ Permiso denegado: revisalo en la configuración del celular."; al tocar Probar de nuevo y elegir "While using the app" mostró "✅ Permiso otorgado." (el permiso de ubicación de Expo Go quedó otorgado). | M27: Claude en VS Code, emulador | N27: 46306
A28: 27 | B28: CA-RF07-1 | C28: RF-07 Modo sin conexión | D28: 4. Ciudadano: sin conexión | E28: vecino1@prueba.ojoalbondi | F28: App | G28: El celular no tiene conexión | H28: Envío un reclamo completo | I28: Se guarda como borrador y veo "Guardado como borrador" | J28: Activar el modo avión para simular la falta de señal. | K28: Pasa | L28: Probado 12/10/2026 con vecino1 y modo avión activado por adb: Crear reporte muestra "📴 Estás sin conexión: el reporte se guarda igual y se envía cuando vuelva la señal.". Con el reclamo completo (501, hacia Villa Rosa, Exceso de pasajeros, interno 2050, "PRUEBA EMULADOR CA-RF07-1") se mostró "Guardado como borrador" — "Sin conexión: se va a enviar solo cuando vuelva la señal.", estado "Borrador local". | M28: Claude (automatizado) | N28: 46307
A29: 28 | B29: CA-RF07-2 | C29: RF-07 Modo sin conexión | D29: 4. Ciudadano: sin conexión | E29: vecino1@prueba.ojoalbondi | F29: App | G29: Tengo borradores guardados | H29: Vuelve la conexión | I29: Los borradores se envían solos, reciben ticket y aparecen en Mis reportes | J29: Activar el modo avión para simular la falta de señal. | K29: Pasa | L29: Probado 12/10/2026: con el borrador de CA-RF07-1, Mis reportes mostraba "1 borrador(es) esperando conexión para enviarse.". Al desactivar el modo avión se envió solo en ~8 s: apareció primero OB-2026-0153 (Recibido), una sola vez en la base. Detalle: sin conexión, Mis reportes no muestra los reclamos ya enviados, solo el aviso del borrador. | M29: Claude (automatizado) | N29: 46307
A30: 29 | B30: CA-RF10-1 | C30: RF-10 Acceso por rol | D30: 5. Institución: acceso y bandeja | E30: tratado@prueba.ojoalbondi | F30: App | G30: Tengo una cuenta de empresa o municipio | H30: Inicio sesión | I30: Entro a la Bandeja de mi organización | K30: Pasa | L30: Probado 12/10/2026: tratado@prueba.ojoalbondi inicia sesión y entra a "BANDEJA DE RECLAMOS — Tratado del Pilar — Líneas habilitadas: 501, 501-503, 503". | M30: Claude (automatizado) | N30: 46307
A31: 30 | B31: CA-RF10-2 | C31: RF-10 Acceso por rol | D31: 5. Institución: acceso y bandeja | E31: vecino1@prueba.ojoalbondi | F31: App | G31: Tengo una cuenta de ciudadano | H31: Navego por toda la app | I31: No veo la Bandeja ni ninguna opción para cambiar estados | K31: Pasa | L31: Probado 12/10/2026 con vecino1: recorrí las 4 pestañas (Reportar, Mapa, Mis reportes, Ajustes) desplazando cada una; en ninguna aparece Bandeja, Cambiar estado, Tomar, Anular, Suscripciones ni Cuentas. Las tarjetas de Mis reportes no abren detalle. | M31: Claude (automatizado) | N31: 46307
A32: 31 | B32: CA-RF11-1 | C32: RF-11 Bandeja de reclamos | D32: 5. Institución: acceso y bandeja | E32: tratado@prueba.ojoalbondi | F32: App | G32: Soy operador de una empresa | H32: Abro la Bandeja | I32: Veo solo los reclamos de mis líneas, los más recientes primero, con ticket, línea, motivo, fecha, estado y antigüedad | K32: Pasa | L32: Probado 12/10/2026 con tratado, filtro Todos: 31 reclamos (los mismos que tiene en la base), solo de las líneas 501, 501-503 y 503, del más reciente al más viejo, cada uno con ticket, línea, antigüedad ("hoy", "hace N días"), motivo, fecha del hecho y estado. Captura: comienzo y final de la lista. | M32: Claude (automatizado) | N32: 46307
A33: 32 | B33: CA-RF11-2 | C33: RF-11 Bandeja de reclamos | D33: 5. Institución: acceso y bandeja | E33: tratado@prueba.ojoalbondi | F33: App | G33: Hay un reclamo Recibido o En revisión con más de 7 días | H33: Abro la Bandeja | I33: Ese reclamo aparece resaltado. Uno Atendido o Anulado con la misma antigüedad no se resalta | J33: Los datos de prueba incluyen reclamos de hasta 45 días. | K33: Pasa | L33: Probado 12/10/2026 con tratado: los Recibido/En revisión de más de 7 días (ej. OB-2026-0010 de 10 días, OB-2026-0081 de 15) tienen borde resaltado y la etiqueta "+7 días"; el Anulado OB-2026-0088 (14 días) y los Atendido OB-2026-0016 y 0117 (15 días) no se resaltan. | M33: Claude (automatizado) | N33: 46307
A34: 33 | B34: CA-RF11-3 | C34: RF-11 Bandeja de reclamos | D34: 5. Institución: acceso y bandeja | E34: Empresa sin suscripción activa | F34: App | G34: No hay reclamos asignados | H34: Abro la Bandeja | I34: Veo un mensaje de que no hay reclamos | J34: Hacerlo durante CA-RF25-5, con la suscripción de Tratado del Pilar suspendida, o crear una cuenta de empresa sin suscripción. | K34: Pasa | L34: Probado 12/10/2026 en la beta con rutabus@prueba.ojoalbondi (511 pendiente), antes de CA-RNF10-2: la Bandeja dice "Sin líneas habilitadas todavía: el administrador tiene que aprobar la suscripción.", contadores en 0 y "No hay reclamos pendientes."; en Todos: "No hay reclamos asignados.". | En la beta: usar rutabus@prueba.ojoalbondi (la 511 está pendiente), antes de CA-RNF10-2. | M34: Claude (automatizado) | N34: 46307
A35: 34 | B35: CA-RF13-1 | C35: RF-13 Detalle del reclamo | D35: 6. Institución: detalle, estado y seguimiento | E35: tratado@prueba.ojoalbondi | F35: App | G35: Estoy en la Bandeja | H35: Toco un reclamo | I35: Veo todos sus datos, la parada en el mapa, la foto si tiene, la descripción y el nombre y apellido del ciudadano | K35: Pasa | L35: Revisión del Cambio N° 43 (12/10/2026). Con tratado, en el detalle de OB-2026-0117 el mapa chico figura en uiautomator como "Mapa con la ubicación del reclamo", clase ImageView, clickable=false y enabled=true: ya no figura como tocable. Con vecino1, en Crear reporte elegí la parada Bolívar e Ituzaingó: el mapa chico sigue siendo un botón ("Cambiar la parada en el mapa", Button, clickable=true) y al tocarlo se abre el mapa de paradas; salí con Cancelar sin enviar. Expo Go se cayó una vez (17:39:13, crash nativo del WebView) al pasar de tratado a vecino1 después de abrir el detalle con el mapa chico, igual que a las 17:10. Captura CA43 (detalle de tratado, formulario con la parada y mapa abierto). | Revisión del Cambio N° 42 (12/10/2026, tratado, OB-2026-0117). Fechas: el detalle y el seguimiento salen con dos dígitos: "Fecha y hora del hecho: 26/09/2026 17:25 hs"; seguimiento "26/09/2026 20:31 hs", "29/09/2026 02:47 hs", "01/10/2026 12:06 hs" (captura CA42-2). Mapa chico: uiautomator lo muestra como "Mapa con la ubicación del reclamo", clase ImageView (rol imagen) y enabled=false; tocarlo no hace nada. Detalle: el nodo sigue con clickable=true (lo pone el Pressable aunque esté deshabilitado); si se quiere que no figure como tocable, usar un View cuando no hay onPress (captura CA42-3). WebView del mapa: con vecino1 usé la pestaña Mapa y el selector de paradas de Crear reporte 15 minutos (17:12 a 17:28, 12 ciclos: mover, acercar con doble toque, tocar paradas, buscar direcciones; sin enviar reclamos, la base no tiene reclamos nuevos). Expo Go se cayó 1 vez, a las 17:23:22, en la pestaña Mapa; y otra a las 17:10:53 al cambiar de tratado (detalle con mapa chico) a vecino1, antes de empezar los 15 minutos. Las dos son el mismo crash nativo: SIGTRAP en el hilo MemoryInfra del proceso principal de Expo Go, dentro de libwebviewchromium. No se vio ningún cierre del proceso del renderer del WebView (no hubo mapa en blanco que volviera solo), así que onRenderProcessGone no llegó a actuar: este crash tira toda la app y el arreglo no lo cubre. Captura CA42-4 (pestaña Mapa al terminar). | Probado 12/10/2026 con tratado en OB-2026-0117: muestra línea, interno, sentido, motivo, fecha y hora, ubicación, descripción, "Ciudadano: Pablo Ruiz" y el mapa chico con la parada (todo igual a la base). Ningún reclamo de prueba tiene a la vez parada y foto: la foto se vio en OB-2026-0154 (captura de CA-RF07-3, a la derecha). Detalles: las fechas del detalle no llevan cero ("26/9/2026", "1/10/2026") a diferencia del resto de la app ("26/09/2026"), y el mapa chico tiene la etiqueta de accesibilidad "Cambiar la parada en el mapa" aunque la empresa no puede cambiarla. | M35: Claude (automatizado) | N35: 46307
A36: 35 | B36: CA-RF13-2 | C36: RF-13 Detalle del reclamo | D36: 6. Institución: detalle, estado y seguimiento | E36: tratado@prueba.ojoalbondi | F36: App | G36: Estoy en el detalle de un reclamo | H36: Reviso los datos del ciudadano | I36: No veo su correo ni su fecha de nacimiento | K36: Pasa | L36: Probado 12/10/2026 con tratado en OB-2026-0117 (y 0151, 0154): del ciudadano solo se ve "Ciudadano: Nombre Apellido"; no aparecen correo ni fecha de nacimiento. | M36: Claude (automatizado) | N36: 46307
A37: 36 | B37: CA-RF14-1 | C37: RF-14 Cambio de estado | D37: 6. Institución: detalle, estado y seguimiento | E37: tratado@prueba.ojoalbondi | F37: App | G37: El reclamo está Recibido | H37: Abro el detalle | I37: Solo puedo pasarlo a En revisión o anularlo | K37: Pasa | L37: Probado 12/10/2026 con tratado en OB-2026-0151 (Recibido, reclamo de prueba): bajo "Cambiar estado" solo hay "Tomar (En revisión)" y "Anular". | Apoyo en la base (11/10/2026): cambiar_estado acepta Recibido → En revisión. Falta mirar la pantalla. | M37: Claude (automatizado) | N37: 46307
A38: 37 | B38: CA-RF14-2 | C38: RF-14 Cambio de estado | D38: 6. Institución: detalle, estado y seguimiento | E38: tratado@prueba.ojoalbondi | F38: App | G38: El reclamo está En revisión | H38: Abro el detalle | I38: Solo puedo marcarlo como Atendido o anularlo | K38: Pasa | L38: Probado 12/10/2026 con tratado: pasé OB-2026-0151 a En revisión (comentario "PRUEBA EMULADOR CA-RF14-2"); ahora solo ofrece "Marcar como Atendido" y "Anular". En la base: Recibido > En revisión. | Apoyo en la base (11/10/2026): rechaza En revisión → Recibido y acepta En revisión → Atendido. Falta mirar la pantalla. | M38: Claude (automatizado) | N38: 46307
A39: 38 | B39: CA-RF14-3 | C39: RF-14 Cambio de estado | D39: 6. Institución: detalle, estado y seguimiento | E39: tratado@prueba.ojoalbondi | F39: App | G39: El reclamo está Atendido o Anulado | H39: Abro el detalle | I39: No hay opciones para cambiar el estado | K39: Pasa | L39: Probado 12/10/2026 con tratado: OB-2026-0151 marcado Atendido ("PRUEBA EMULADOR CA-RF14-3") y OB-2026-0152 Anulado (motivo "PRUEBA EMULADOR CA-RF14-3"): en los dos, "Cambiar estado" muestra "Estado final: no admite más cambios." sin botones. Solo se cambiaron 0151 y 0152; 0153 y 0154 siguen Recibido. | Apoyo en la base (11/10/2026): rechaza Atendido → Anulado. Falta mirar la pantalla. | M39: Claude (automatizado) | N39: 46307
A40: 39 | B40: CA-RF14-4 | C40: RF-14 Cambio de estado | D40: 6. Institución: detalle, estado y seguimiento | E40: tratado@prueba.ojoalbondi | F40: App | G40: Elegí Anular | H40: Confirmo sin escribir un motivo | I40: Se muestra "El motivo de anulación es obligatorio." y el estado no cambia | K40: Pasa | L40: Probado 12/10/2026 con tratado en OB-2026-0152: "Anular" abre "Anular reclamo" (motivos rápidos, campo "Motivo de anulación", Confirmar/Cancelar); al confirmar sin motivo se muestra "El motivo de anulación es obligatorio." y en la base siguió Recibido con una sola entrada. | Apoyo en la base (11/10/2026): anular sin motivo da "El motivo de anulación es obligatorio.". Falta mirar la pantalla. | M40: Claude (automatizado) | N40: 46307
A41: 40 | B41: CA-RF14-5 | C41: RF-14 Cambio de estado | D41: 6. Institución: detalle, estado y seguimiento | E41: tratado@prueba.ojoalbondi | F41: Base de datos | G41: Un reclamo está Recibido | H41: Se intenta pasarlo directo a Atendido, incluso desde fuera de la app | I41: La base de datos rechaza el cambio | J41: Como tratado@prueba.ojoalbondi: select cambiar_estado('<id de un reclamo Recibido de la 501>', 'Atendido', 'x'); → error 'Cambio de estado no permitido' | K41: Pasa | L41: Como tratado: "Cambio de estado no permitido: Recibido → Atendido". Como vecino1: "No tenés permiso para gestionar este reclamo". | M41: Claude (SQL en la beta, en nombre de la cuenta del caso) | N41: 46306
A42: 41 | B42: CA-RF15-1 | C42: RF-15 Seguimiento | D42: 6. Institución: detalle, estado y seguimiento | E42: tratado@prueba.ojoalbondi | F42: App | G42: Un reclamo tuvo cambios de estado | H42: Abro su detalle | I42: Veo cada cambio en orden, con estado, fecha y hora, organización y comentario | K42: Pasa | L42: Probado 12/10/2026 con tratado en OB-2026-0117: Seguimiento muestra en orden Recibido (26/9/2026 20:31, Sistema: reclamo recibido.), En revisión (29/9/2026 02:47, Tratado del Pilar: Estamos revisando...) y Atendido (1/10/2026 12:06, Tratado del Pilar: Se reforzó la frecuencia...), igual que historial_estados. | M42: Claude (automatizado) | N42: 46307
A43: 42 | B43: CA-RF15-2 | C43: RF-15 Seguimiento | D43: 6. Institución: detalle, estado y seguimiento | E43: tratado@prueba.ojoalbondi | F43: App | G43: Un reclamo recién se creó | H43: Abro su detalle | I43: Veo una sola entrada: Recibido, registrada por el Sistema | K43: Pasa | L43: Probado 12/10/2026 con tratado en OB-2026-0151 recién creado (antes de CA-RF14): una sola entrada, Recibido, 12/10/2026 12:19, "Sistema: reclamo recibido.". | Apoyo en la base (11/10/2026): un reclamo nuevo tiene una sola entrada, Recibido, registrada por Sistema. Falta mirar la pantalla. | M43: Claude (automatizado) | N43: 46307
...

Sheet Resumen
A1: Resumen de avance
A3: Total | B3: Pasa | C3: Falla | D3: Bloqueado | E3: Sin probar | F3: % aprobado
A4: =COUNTA('Plan de pruebas'!$B$2:$B$300) | B4: =COUNTIF('Plan de pruebas'!$K$2:$K$300,"Pasa") | C4: =COUNTIF('Plan de pruebas'!$K$2:$K$300,"Falla") | D4: =COUNTIF('Plan de pruebas'!$K$2:$K$300,"Bloqueado") | E4: =A4-B4-C4-D4 | F4: =IF(A4=0,0,B4/A4)
A6: Requerimiento | B6: Criterios | C6: Pasa | D6: Falla | E6: Bloqueado | F6: Sin probar | G6: Estado
A7: RF-01 Registro | B7: =COUNTIF('Plan de pruebas'!$C$2:$C$300,A7) | C7: =COUNTIFS('Plan de pruebas'!$C$2:$C$300,$A7,'Plan de pruebas'!$K$2:$K$300,"Pasa") | D7: =COUNTIFS('Plan de pruebas'!$C$2:$C$300,$A7,'Plan de pruebas'!$K$2:$K$300,"Falla") | E7: =COUNTIFS('Plan de pruebas'!$C$2:$C$300,$A7,'Plan de pruebas'!$K$2:$K$300,"Bloqueado") | F7: =B7-C7-D7-E7 | G7: =IF(C7=B7,"Cumplido",IF(D7>0,"Con fallas",IF(C7+D7+E7=0,"Sin probar","En curso")))
A8: RF-02 Inicio de sesión | B8: =COUNTIF('Plan de pruebas'!$C$2:$C$300,A8) | C8: =COUNTIFS('Plan de pruebas'!$C$2:$C$300,$A8,'Plan de pruebas'!$K$2:$K$300,"Pasa") | D8: =COUNTIFS('Plan de pruebas'!$C$2:$C$300,$A8,'Plan de pruebas'!$K$2:$K$300,"Falla") | E8: =COUNTIFS('Plan de pruebas'!$C$2:$C$300,$A8,'Plan de pruebas'!$K$2:$K$300,"Bloqueado") | F8: =B8-C8-D8-E8 | G8: =IF(C8=B8,"Cumplido",IF(D8>0,"Con fallas",IF(C8+D8+E8=0,"Sin probar","En curso")))
A9: RN-02 Cuentas institucionales | B9: =COUNTIF('Plan de pruebas'!$C$2:$C$300,A9) | C9: =COUNTIFS('Plan de pruebas'!$C$2:$C$300,$A9,'Plan de pruebas'!$K$2:$K$300,"Pasa") | D9: =COUNTIFS('Plan de pruebas'!$C$2:$C$300,$A9,'Plan de pruebas'!$K$2:$K$300,"Falla") | E9: =COUNTIFS('Plan de pruebas'!$C$2:$C$300,$A9,'Plan de pruebas'!$K$2:$K$300,"Bloqueado") | F9: =B9-C9-D9-E9 | G9: =IF(C9=B9,"Cumplido",IF(D9>0,"Con fallas",IF(C9+D9+E9=0,"Sin probar","En curso")))
A10: RF-03 Crear reclamo | B10: =COUNTIF('Plan de pruebas'!$C$2:$C$300,A10) | C10: =COUNTIFS('Plan de pruebas'!$C$2:$C$300,$A10,'Plan de pruebas'!$K$2:$K$300,"Pasa") | D10: =COUNTIFS('Plan de pruebas'!$C$2:$C$300,$A10,'Plan de pruebas'!$K$2:$K$300,"Falla") | E10: =COUNTIFS('Plan de pruebas'!$C$2:$C$300,$A10,'Plan de pruebas'!$K$2:$K$300,"Bloqueado") | F10: =B10-C10-D10-E10 | G10: =IF(C10=B10,"Cumplido",IF(D10>0,"Con fallas",IF(C10+D10+E10=0,"Sin probar","En curso")))
A11: RF-04 Confirmación | B11: =COUNTIF('Plan de pruebas'!$C$2:$C$300,A11) | C11: =COUNTIFS('Plan de pruebas'!$C$2:$C$300,$A11,'Plan de pruebas'!$K$2:$K$300,"Pasa") | D11: =COUNTIFS('Plan de pruebas'!$C$2:$C$300,$A11,'Plan de pruebas'!$K$2:$K$300,"Falla") | E11: =COUNTIFS('Plan de pruebas'!$C$2:$C$300,$A11,'Plan de pruebas'!$K$2:$K$300,"Bloqueado") | F11: =B11-C11-D11-E11 | G11: =IF(C11=B11,"Cumplido",IF(D11>0,"Con fallas",IF(C11+D11+E11=0,"Sin probar","En curso")))
A12: RF-05 Inicio y Mis reportes | B12: =COUNTIF('Plan de pruebas'!$C$2:$C$300,A12) | C12: =COUNTIFS('Plan de pruebas'!$C$2:$C$300,$A12,'Plan de pruebas'!$K$2:$K$300,"Pasa") | D12: =COUNTIFS('Plan de pruebas'!$C$2:$C$300,$A12,'Plan de pruebas'!$K$2:$K$300,"Falla") | E12: =COUNTIFS('Plan de pruebas'!$C$2:$C$300,$A12,'Plan de pruebas'!$K$2:$K$300,"Bloqueado") | F12: =B12-C12-D12-E12 | G12: =IF(C12=B12,"Cumplido",IF(D12>0,"Con fallas",IF(C12+D12+E12=0,"Sin probar","En curso")))
A13: RF-06 Ajustes | B13: =COUNTIF('Plan de pruebas'!$C$2:$C$300,A13) | C13: =COUNTIFS('Plan de pruebas'!$C$2:$C$300,$A13,'Plan de pruebas'!$K$2:$K$300,"Pasa") | D13: =COUNTIFS('Plan de pruebas'!$C$2:$C$300,$A13,'Plan de pruebas'!$K$2:$K$300,"Falla") | E13: =COUNTIFS('Plan de pruebas'!$C$2:$C$300,$A13,'Plan de pruebas'!$K$2:$K$300,"Bloqueado") | F13: =B13-C13-D13-E13 | G13: =IF(C13=B13,"Cumplido",IF(D13>0,"Con fallas",IF(C13+D13+E13=0,"Sin probar","En curso")))
A14: RF-07 Modo sin conexión | B14: =COUNTIF('Plan de pruebas'!$C$2:$C$300,A14) | C14: =COUNTIFS('Plan de pruebas'!$C$2:$C$300,$A14,'Plan de pruebas'!$K$2:$K$300,"Pasa") | D14: =COUNTIFS('Plan de pruebas'!$C$2:$C$300,$A14,'Plan de pruebas'!$K$2:$K$300,"Falla") | E14: =COUNTIFS('Plan de pruebas'!$C$2:$C$300,$A14,'Plan de pruebas'!$K$2:$K$300,"Bloqueado") | F14: =B14-C14-D14-E14 | G14: =IF(C14=B14,"Cumplido",IF(D14>0,"Con fallas",IF(C14+D14+E14=0,"Sin probar","En curso")))
A15: RF-10 Acceso por rol | B15: =COUNTIF('Plan de pruebas'!$C$2:$C$300,A15) | C15: =COUNTIFS('Plan de pruebas'!$C$2:$C$300,$A15,'Plan de pruebas'!$K$2:$K$300,"Pasa") | D15: =COUNTIFS('Plan de pruebas'!$C$2:$C$300,$A15,'Plan de pruebas'!$K$2:$K$300,"Falla") | E15: =COUNTIFS('Plan de pruebas'!$C$2:$C$300,$A15,'Plan de pruebas'!$K$2:$K$300,"Bloqueado") | F15: =B15-C15-D15-E15 | G15: =IF(C15=B15,"Cumplido",IF(D15>0,"Con fallas",IF(C15+D15+E15=0,"Sin probar","En curso")))
A16: RF-11 Bandeja de reclamos | B16: =COUNTIF('Plan de pruebas'!$C$2:$C$300,A16) | C16: =COUNTIFS('Plan de pruebas'!$C$2:$C$300,$A16,'Plan de pruebas'!$K$2:$K$300,"Pasa") | D16: =COUNTIFS('Plan de pruebas'!$C$2:$C$300,$A16,'Plan de pruebas'!$K$2:$K$300,"Falla") | E16: =COUNTIFS('Plan de pruebas'!$C$2:$C$300,$A16,'Plan de pruebas'!$K$2:$K$300,"Bloqueado") | F16: =B16-C16-D16-E16 | G16: =IF(C16=B16,"Cumplido",IF(D16>0,"Con fallas",IF(C16+D16+E16=0,"Sin probar","En curso")))
A17: RF-13 Detalle del reclamo | B17: =COUNTIF('Plan de pruebas'!$C$2:$C$300,A17) | C17: =COUNTIFS('Plan de pruebas'!$C$2:$C$300,$A17,'Plan de pruebas'!$K$2:$K$300,"Pasa") | D17: =COUNTIFS('Plan de pruebas'!$C$2:$C$300,$A17,'Plan de pruebas'!$K$2:$K$300,"Falla") | E17: =COUNTIFS('Plan de pruebas'!$C$2:$C$300,$A17,'Plan de pruebas'!$K$2:$K$300,"Bloqueado") | F17: =B17-C17-D17-E17 | G17: =IF(C17=B17,"Cumplido",IF(D17>0,"Con fallas",IF(C17+D17+E17=0,"Sin probar","En curso")))
A18: RF-14 Cambio de estado | B18: =COUNTIF('Plan de pruebas'!$C$2:$C$300,A18) | C18: =COUNTIFS('Plan de pruebas'!$C$2:$C$300,$A18,'Plan de pruebas'!$K$2:$K$300,"Pasa") | D18: =COUNTIFS('Plan de pruebas'!$C$2:$C$300,$A18,'Plan de pruebas'!$K$2:$K$300,"Falla") | E18: =COUNTIFS('Plan de pruebas'!$C$2:$C$300,$A18,'Plan de pruebas'!$K$2:$K$300,"Bloqueado") | F18: =B18-C18-D18-E18 | G18: =IF(C18=B18,"Cumplido",IF(D18>0,"Con fallas",IF(C18+D18+E18=0,"Sin probar","En curso")))
... A24: RNF-06 Accesibilidad | B24: =COUNTIF('Plan de pruebas'!$C$2:$C$300,A24) | C24: =COUNTIFS('Plan de pruebas'!$C$2:$C$300,$A24,'Plan de pruebas'!$K$2:$K$300,"Pasa") | D24: =COUNTIFS('Plan de pruebas'!$C$2:$C$300,$A24,'Plan de pruebas'!$K$2:$K$300,"Falla") | E24: =COUNTIFS('Plan de pruebas'!$C$2:$C$300,$A24,'Plan de pruebas'!$K$2:$K$300,"Bloqueado") | F24: =B24-C24-D24-E24 | G24: =IF(C24=B24,"Cumplido",IF(D24>0,"Con fallas",IF(C24+D24+E24=0,"Sin probar","En curso")))
A26: Se calcula solo a partir de la hoja "Plan de pruebas". No editar.
